Failure # 1 (occurred at 2020-09-21_16-01-06)
Traceback (most recent call last):
  File "/home/kamran/rlfd_env/lib/python3.6/site-packages/ray/tune/trial_runner.py", line 471, in _process_trial
    result = self.trial_executor.fetch_result(trial)
  File "/home/kamran/rlfd_env/lib/python3.6/site-packages/ray/tune/ray_trial_executor.py", line 430, in fetch_result
    result = ray.get(trial_future[0], DEFAULT_GET_TIMEOUT)
  File "/home/kamran/rlfd_env/lib/python3.6/site-packages/ray/worker.py", line 1538, in get
    raise value.as_instanceof_cause()
ray.exceptions.RayTaskError(TuneError): [36mray::ImplicitFunc.train()[39m (pid=6335, ip=142.1.44.25)
  File "python/ray/_raylet.pyx", line 479, in ray._raylet.execute_task
  File "python/ray/_raylet.pyx", line 432, in ray._raylet.execute_task.function_executor
  File "/home/kamran/rlfd_env/lib/python3.6/site-packages/ray/tune/trainable.py", line 332, in train
    result = self.step()
  File "/home/kamran/rlfd_env/lib/python3.6/site-packages/ray/tune/function_runner.py", line 337, in step
    self._report_thread_runner_error(block=True)
  File "/home/kamran/rlfd_env/lib/python3.6/site-packages/ray/tune/function_runner.py", line 456, in _report_thread_runner_error
    .format(err_tb_str)))
ray.tune.error.TuneError: Trial raised an exception. Traceback:
[36mray::ImplicitFunc.train()[39m (pid=6335, ip=142.1.44.25)
  File "/home/kamran/rlfd_env/lib/python3.6/site-packages/ray/tune/function_runner.py", line 224, in run
    self._entrypoint()
  File "/home/kamran/rlfd_env/lib/python3.6/site-packages/ray/tune/function_runner.py", line 287, in entrypoint
    self._status_reporter.get_checkpoint())
  File "/home/kamran/rlfd_env/lib/python3.6/site-packages/ray/tune/function_runner.py", line 507, in _trainable_func
    output = train_func(config)
  File "/home/kamran/rlfd/rlfd/rlfd/train.py", line 224, in main
    agent.train_online()
  File "/home/kamran/rlfd/rlfd/rlfd/agents/mbpo.py", line 183, in train_online
    batch = self.sample_batch()
  File "/home/kamran/rlfd/rlfd/rlfd/agents/mbpo.py", line 159, in sample_batch
    model_batch = self.model_buffer.sample(model_batch_size)
  File "/home/kamran/rlfd/rlfd/rlfd/memory.py", line 89, in sample
    return self._sample_random(batch_size)
  File "/home/kamran/rlfd/rlfd/rlfd/memory.py", line 188, in _sample_random
    inds = np.random.randint(0, self.stored_steps, batch_size)
  File "mtrand.pyx", line 743, in numpy.random.mtrand.RandomState.randint
  File "_bounded_integers.pyx", line 1269, in numpy.random._bounded_integers._rand_int64
TypeError: 'float' object cannot be interpreted as an integer

